Workbook
Name TownshipList: 'Lists'!$A$2:$A$57
Name TierList: 'Lists'!$B$2:$B$4
Name AmountEntryTypeList: 'Lists'!$C$2:$C$6
Name StatusList: 'Lists'!$D$2:$D$6
Name EnvironmentList: 'Lists'!$E$2:$E$4

Sheet Sheet1
A1: id | B1: way_id | C1: customer_id | D1: merchant_id | E1: status | F1: recipient_name | G1: recipient_phone | H1: township | I1: delivery_address | J1: item_price | K1: delivery_charges | L1: cod_amount | M1: weight_kg | N1: created_at | O1: updated_at | P1: environment | Q1: customer_tier | R1: monthly_ways | S1: amount_entry_type | T1: merchant_stated_total_amount | U1: additional_customer_charge | V1: cbm_surcharge | W1: other_surcharge | X1: merchant_payable_charges | Y1: other_merchant_credits | Z1: remarks | AA1: entered_by | AB1: authorized_by | AC1: tariff_zone | AD1: tariff_zone_code | AE1: base_tariff | AF1: included_kg | AG1: extra_per_kg | AH1: commitment_min_ways | AI1: commitment_refund_per_way | AJ1: chargeable_weight_kg | AK1: extra_kg | AL1: weight_surcharge | AM1: gross_system_delivery_charge | AN1: commitment_refund | AO1: net_system_delivery_charge | AP1: effective_declared_delivery_charge | AQ1: delivery_difference | AR1: settlement_direction | AS1: merchant_settlement_adjustment | AT1: merchant_final_settlement_amount | AU1: validation_status | AV1: validation_message | AW1: calculation_version | AX1: calculated_at
L2: =IF($S2="","",IF($S2="ITEM_PRICE_PLUS_DECLARED_DELIVERY",IF(OR($J2="",$K2=""),"",SUM($J2,$K2,$U2)),IF($S2="TOTAL_AMOUNT_INCLUDING_DELIVERY",IF($T2="","",$T2),IF($S2="DELIVERY_CHARGE_ONLY",IF($K2="","",SUM($K2,$U2)),IF($S2="EXACT_COLLECTION_AMOUNT",IF($T2="","",$T2),IF($S2="ITEM_PRICE_ONLY_DELIVERY_PAID_BY_MERCHANT",IF($J2="","",SUM($J2,$U2)),"")))))) | AC2: =IFERROR(VLOOKUP($H2&"|"&$Q2,Tariff_Master!$A$2:$L$169,3,FALSE),"") | AD2: =IFERROR(VLOOKUP($H2&"|"&$Q2,Tariff_Master!$A$2:$L$169,4,FALSE),"") | AE2: =IFERROR(VLOOKUP($H2&"|"&$Q2,Tariff_Master!$A$2:$L$169,6,FALSE),"") | AF2: =IFERROR(VLOOKUP($H2&"|"&$Q2,Tariff_Master!$A$2:$L$169,7,FALSE),"") | AG2: =IFERROR(VLOOKUP($H2&"|"&$Q2,Tariff_Master!$A$2:$L$169,8,FALSE),"") | AH2: =IFERROR(VLOOKUP($H2&"|"&$Q2,Tariff_Master!$A$2:$L$169,9,FALSE),"") | AI2: =IFERROR(VLOOKUP($H2&"|"&$Q2,Tariff_Master!$A$2:$L$169,10,FALSE),"") | AJ2: =IF($M2="","",ROUNDUP(MAX(0,$M2),0)) | AK2: =IF(OR($AJ2="",$AF2=""),"",MAX(0,$AJ2-$AF2)) | AL2: =IF(OR($AK2="",$AG2=""),"",MAX(0,$AK2*$AG2)) | AM2: =IF($AE2="","",MAX(0,SUM($AE2,$AL2,$V2,$W2))) | AN2: =IF($AM2="","",IF(AND($Q2="COMMITMENT",$R2>=$AH2),$AI2,0)) | AO2: =IF($AM2="","",MAX(0,$AM2-$AN2)) | AP2: =IF($S2="","",IF(OR($S2="ITEM_PRICE_PLUS_DECLARED_DELIVERY",$S2="DELIVERY_CHARGE_ONLY"),$K2,IF($S2="TOTAL_AMOUNT_INCLUDING_DELIVERY",IF(OR($T2="",$J2=""),"",MAX(0,$T2-$J2-$U2)),IF($S2="ITEM_PRICE_ONLY_DELIVERY_PAID_BY_MERCHANT",0,"")))) | AQ2: =IF(OR($AP2="",$AO2=""),"",$AP2-$AO2) | AR2: =IF($S2="EXACT_COLLECTION_AMOUNT","BREAKDOWN_REQUIRED",IF($AQ2="","",IF($AQ2>0,"CREDIT_TO_MERCHANT",IF($AQ2<0,"DEDUCT_FROM_MERCHANT","NO_ADJUSTMENT")))) | AS2: =IF(OR($AQ2="",$AR2="BREAKDOWN_REQUIRED"),"",$AQ2) | AT2: =IF(OR($AR2="",$AR2="BREAKDOWN_REQUIRED"),"",SUM($J2,$AQ2,$Y2)-$X2) | AU2: =IF(AND($A2="",$B2="",$F2="",$H2="",$J2="",$K2="",$M2="",$S2=""),"",IF(OR($H2="",$Q2="",$M2="",$S2=""),"ERROR",IF(OR($J2<0,$K2<0,$M2<0,$T2<0,$U2<0,$V2<0,$W2<0,$X2<0,$Y2<0),"ERROR",IF($AE2="","ERROR",IF(AND(OR($S2="ITEM_PRICE_PLUS_DECLARED_DELIVERY",$S2="TOTAL_AMOUNT_INCLUDING_DELIVERY",$S2="ITEM_PRICE_ONLY_DELIVERY_PAID_BY_MERCHANT"),$J2=""),"ERROR",IF(AND(OR($S2="ITEM_PRICE_PLUS_DECLARED_DELIVERY",$S2="DELIVERY_CHARGE_ONLY"),$K2=""),"ERROR",IF(AND(OR($S2="TOTAL_AMOUNT_INCLUDING_DELIVERY",$S2="EXACT_COLLECTION_AMOUNT"),$T2=""),"ERROR",IF(AND($S2="TOTAL_AMOUNT_INCLUDING_DELIVERY",$T2<SUM($J2,$U2)),"ERROR",IF($S2="EXACT_COLLECTION_AMOUNT","REVIEW","OK"))))))))) | AV2: =IF($AU2="","",IF($H2="","Township required",IF($Q2="","Customer tier required",IF($M2="","Weight required",IF($S2="","Amount entry type required",IF(OR($J2<0,$K2<0,$M2<0,$T2<0,$U2<0,$V2<0,$W2<0,$X2<0,$Y2<0),"Negative amounts are not allowed",IF($AE2="","Tariff not found for township and tier",IF(AND(OR($S2="ITEM_PRICE_PLUS_DECLARED_DELIVERY",$S2="TOTAL_AMOUNT_INCLUDING_DELIVERY",$S2="ITEM_PRICE_ONLY_DELIVERY_PAID_BY_MERCHANT"),$J2=""),"Item price required for this amount type",IF(AND(OR($S2="ITEM_PRICE_PLUS_DECLARED_DELIVERY",$S2="DELIVERY_CHARGE_ONLY"),$K2=""),"Declared delivery charge required",IF(AND(OR($S2="TOTAL_AMOUNT_INCLUDING_DELIVERY",$S2="EXACT_COLLECTION_AMOUNT"),$T2=""),"Stated total amount required",IF(AND($S2="TOTAL_AMOUNT_INCLUDING_DELIVERY",$T2<SUM($J2,$U2)),"Stated total is below item price plus additional charge",IF($S2="EXACT_COLLECTION_AMOUNT","Authorized amount breakdown required before settlement","Ready for collection and settlement")))))))))))) | AW2: =IF($AU2="","","PARCEL_FINANCIAL_V2")
L3: =IF($S3="","",IF($S3="ITEM_PRICE_PLUS_DECLARED_DELIVERY",IF(OR($J3="",$K3=""),"",SUM($J3,$K3,$U3)),IF($S3="TOTAL_AMOUNT_INCLUDING_DELIVERY",IF($T3="","",$T3),IF($S3="DELIVERY_CHARGE_ONLY",IF($K3="","",SUM($K3,$U3)),IF($S3="EXACT_COLLECTION_AMOUNT",IF($T3="","",$T3),IF($S3="ITEM_PRICE_ONLY_DELIVERY_PAID_BY_MERCHANT",IF($J3="","",SUM($J3,$U3)),"")))))) | AC3: =IFERROR(VLOOKUP($H3&"|"&$Q3,Tariff_Master!$A$2:$L$169,3,FALSE),"") | AD3: =IFERROR(VLOOKUP($H3&"|"&$Q3,Tariff_Master!$A$2:$L$169,4,FALSE),"") | AE3: =IFERROR(VLOOKUP($H3&"|"&$Q3,Tariff_Master!$A$2:$L$169,6,FALSE),"") | AF3: =IFERROR(VLOOKUP($H3&"|"&$Q3,Tariff_Master!$A$2:$L$169,7,FALSE),"") | AG3: =IFERROR(VLOOKUP($H3&"|"&$Q3,Tariff_Master!$A$2:$L$169,8,FALSE),"") | AH3: =IFERROR(VLOOKUP($H3&"|"&$Q3,Tariff_Master!$A$2:$L$169,9,FALSE),"") | AI3: =IFERROR(VLOOKUP($H3&"|"&$Q3,Tariff_Master!$A$2:$L$169,10,FALSE),"") | AJ3: =IF($M3="","",ROUNDUP(MAX(0,$M3),0)) | AK3: =IF(OR($AJ3="",$AF3=""),"",MAX(0,$AJ3-$AF3)) | AL3: =IF(OR($AK3="",$AG3=""),"",MAX(0,$AK3*$AG3)) | AM3: =IF($AE3="","",MAX(0,SUM($AE3,$AL3,$V3,$W3))) | AN3: =IF($AM3="","",IF(AND($Q3="COMMITMENT",$R3>=$AH3),$AI3,0)) | AO3: =IF($AM3="","",MAX(0,$AM3-$AN3)) | AP3: =IF($S3="","",IF(OR($S3="ITEM_PRICE_PLUS_DECLARED_DELIVERY",$S3="DELIVERY_CHARGE_ONLY"),$K3,IF($S3="TOTAL_AMOUNT_INCLUDING_DELIVERY",IF(OR($T3="",$J3=""),"",MAX(0,$T3-$J3-$U3)),IF($S3="ITEM_PRICE_ONLY_DELIVERY_PAID_BY_MERCHANT",0,"")))) | AQ3: =IF(OR($AP3="",$AO3=""),"",$AP3-$AO3) | AR3: =IF($S3="EXACT_COLLECTION_AMOUNT","BREAKDOWN_REQUIRED",IF($AQ3="","",IF($AQ3>0,"CREDIT_TO_MERCHANT",IF($AQ3<0,"DEDUCT_FROM_MERCHANT","NO_ADJUSTMENT")))) | AS3: =IF(OR($AQ3="",$AR3="BREAKDOWN_REQUIRED"),"",$AQ3) | AT3: =IF(OR($AR3="",$AR3="BREAKDOWN_REQUIRED"),"",SUM($J3,$AQ3,$Y3)-$X3) | AU3: =IF(AND($A3="",$B3="",$F3="",$H3="",$J3="",$K3="",$M3="",$S3=""),"",IF(OR($H3="",$Q3="",$M3="",$S3=""),"ERROR",IF(OR($J3<0,$K3<0,$M3<0,$T3<0,$U3<0,$V3<0,$W3<0,$X3<0,$Y3<0),"ERROR",IF($AE3="","ERROR",IF(AND(OR($S3="ITEM_PRICE_PLUS_DECLARED_DELIVERY",$S3="TOTAL_AMOUNT_INCLUDING_DELIVERY",$S3="ITEM_PRICE_ONLY_DELIVERY_PAID_BY_MERCHANT"),$J3=""),"ERROR",IF(AND(OR($S3="ITEM_PRICE_PLUS_DECLARED_DELIVERY",$S3="DELIVERY_CHARGE_ONLY"),$K3=""),"ERROR",IF(AND(OR($S3="TOTAL_AMOUNT_INCLUDING_DELIVERY",$S3="EXACT_COLLECTION_AMOUNT"),$T3=""),"ERROR",IF(AND($S3="TOTAL_AMOUNT_INCLUDING_DELIVERY",$T3<SUM($J3,$U3)),"ERROR",IF($S3="EXACT_COLLECTION_AMOUNT","REVIEW","OK"))))))))) | AV3: =IF($AU3="","",IF($H3="","Township required",IF($Q3="","Customer tier required",IF($M3="","Weight required",IF($S3="","Amount entry type required",IF(OR($J3<0,$K3<0,$M3<0,$T3<0,$U3<0,$V3<0,$W3<0,$X3<0,$Y3<0),"Negative amounts are not allowed",IF($AE3="","Tariff not found for township and tier",IF(AND(OR($S3="ITEM_PRICE_PLUS_DECLARED_DELIVERY",$S3="TOTAL_AMOUNT_INCLUDING_DELIVERY",$S3="ITEM_PRICE_ONLY_DELIVERY_PAID_BY_MERCHANT"),$J3=""),"Item price required for this amount type",IF(AND(OR($S3="ITEM_PRICE_PLUS_DECLARED_DELIVERY",$S3="DELIVERY_CHARGE_ONLY"),$K3=""),"Declared delivery charge required",IF(AND(OR($S3="TOTAL_AMOUNT_INCLUDING_DELIVERY",$S3="EXACT_COLLECTION_AMOUNT"),$T3=""),"Stated total amount required",IF(AND($S3="TOTAL_AMOUNT_INCLUDING_DELIVERY",$T3<SUM($J3,$U3)),"Stated total is below item price plus additional charge",IF($S3="EXACT_COLLECTION_AMOUNT","Authorized amount breakdown required before settlement","Ready for collection and settlement")))))))))))) | AW3: =IF($AU3="","","PARCEL_FINANCIAL_V2")
L4: =IF($S4="","",IF($S4="ITEM_PRICE_PLUS_DECLARED_DELIVERY",IF(OR($J4="",$K4=""),"",SUM($J4,$K4,$U4)),IF($S4="TOTAL_AMOUNT_INCLUDING_DELIVERY",IF($T4="","",$T4),IF($S4="DELIVERY_CHARGE_ONLY",IF($K4="","",SUM($K4,$U4)),IF($S4="EXACT_COLLECTION_AMOUNT",IF($T4="","",$T4),IF($S4="ITEM_PRICE_ONLY_DELIVERY_PAID_BY_MERCHANT",IF($J4="","",SUM($J4,$U4)),"")))))) | AC4: =IFERROR(VLOOKUP($H4&"|"&$Q4,Tariff_Master!$A$2:$L$169,3,FALSE),"") | AD4: =IFERROR(VLOOKUP($H4&"|"&$Q4,Tariff_Master!$A$2:$L$169,4,FALSE),"") | AE4: =IFERROR(VLOOKUP($H4&"|"&$Q4,Tariff_Master!$A$2:$L$169,6,FALSE),"") | AF4: =IFERROR(VLOOKUP($H4&"|"&$Q4,Tariff_Master!$A$2:$L$169,7,FALSE),"") | AG4: =IFERROR(VLOOKUP($H4&"|"&$Q4,Tariff_Master!$A$2:$L$169,8,FALSE),"") | AH4: =IFERROR(VLOOKUP($H4&"|"&$Q4,Tariff_Master!$A$2:$L$169,9,FALSE),"") | AI4: =IFERROR(VLOOKUP($H4&"|"&$Q4,Tariff_Master!$A$2:$L$169,10,FALSE),"") | AJ4: =IF($M4="","",ROUNDUP(MAX(0,$M4),0)) | AK4: =IF(OR($AJ4="",$AF4=""),"",MAX(0,$AJ4-$AF4)) | AL4: =IF(OR($AK4="",$AG4=""),"",MAX(0,$AK4*$AG4)) | AM4: =IF($AE4="","",MAX(0,SUM($AE4,$AL4,$V4,$W4))) | AN4: =IF($AM4="","",IF(AND($Q4="COMMITMENT",$R4>=$AH4),$AI4,0)) | AO4: =IF($AM4="","",MAX(0,$AM4-$AN4)) | AP4: =IF($S4="","",IF(OR($S4="ITEM_PRICE_PLUS_DECLARED_DELIVERY",$S4="DELIVERY_CHARGE_ONLY"),$K4,IF($S4="TOTAL_AMOUNT_INCLUDING_DELIVERY",IF(OR($T4="",$J4=""),"",MAX(0,$T4-$J4-$U4)),IF($S4="ITEM_PRICE_ONLY_DELIVERY_PAID_BY_MERCHANT",0,"")))) | AQ4: =IF(OR($AP4="",$AO4=""),"",$AP4-$AO4) | AR4: =IF($S4="EXACT_COLLECTION_AMOUNT","BREAKDOWN_REQUIRED",IF($AQ4="","",IF($AQ4>0,"CREDIT_TO_MERCHANT",IF($AQ4<0,"DEDUCT_FROM_MERCHANT","NO_ADJUSTMENT")))) | AS4: =IF(OR($AQ4="",$AR4="BREAKDOWN_REQUIRED"),"",$AQ4) | AT4: =IF(OR($AR4="",$AR4="BREAKDOWN_REQUIRED"),"",SUM($J4,$AQ4,$Y4)-$X4) | AU4: =IF(AND($A4="",$B4="",$F4="",$H4="",$J4="",$K4="",$M4="",$S4=""),"",IF(OR($H4="",$Q4="",$M4="",$S4=""),"ERROR",IF(OR($J4<0,$K4<0,$M4<0,$T4<0,$U4<0,$V4<0,$W4<0,$X4<0,$Y4<0),"ERROR",IF($AE4="","ERROR",IF(AND(OR($S4="ITEM_PRICE_PLUS_DECLARED_DELIVERY",$S4="TOTAL_AMOUNT_INCLUDING_DELIVERY",$S4="ITEM_PRICE_ONLY_DELIVERY_PAID_BY_MERCHANT"),$J4=""),"ERROR",IF(AND(OR($S4="ITEM_PRICE_PLUS_DECLARED_DELIVERY",$S4="DELIVERY_CHARGE_ONLY"),$K4=""),"ERROR",IF(AND(OR($S4="TOTAL_AMOUNT_INCLUDING_DELIVERY",$S4="EXACT_COLLECTION_AMOUNT"),$T4=""),"ERROR",IF(AND($S4="TOTAL_AMOUNT_INCLUDING_DELIVERY",$T4<SUM($J4,$U4)),"ERROR",IF($S4="EXACT_COLLECTION_AMOUNT","REVIEW","OK"))))))))) | AV4: =IF($AU4="","",IF($H4="","Township required",IF($Q4="","Customer tier required",IF($M4="","Weight required",IF($S4="","Amount entry type required",IF(OR($J4<0,$K4<0,$M4<0,$T4<0,$U4<0,$V4<0,$W4<0,$X4<0,$Y4<0),"Negative amounts are not allowed",IF($AE4="","Tariff not found for township and tier",IF(AND(OR($S4="ITEM_PRICE_PLUS_DECLARED_DELIVERY",$S4="TOTAL_AMOUNT_INCLUDING_DELIVERY",$S4="ITEM_PRICE_ONLY_DELIVERY_PAID_BY_MERCHANT"),$J4=""),"Item price required for this amount type",IF(AND(OR($S4="ITEM_PRICE_PLUS_DECLARED_DELIVERY",$S4="DELIVERY_CHARGE_ONLY"),$K4=""),"Declared delivery charge required",IF(AND(OR($S4="TOTAL_AMOUNT_INCLUDING_DELIVERY",$S4="EXACT_COLLECTION_AMOUNT"),$T4=""),"Stated total amount required",IF(AND($S4="TOTAL_AMOUNT_INCLUDING_DELIVERY",$T4<SUM($J4,$U4)),"Stated total is below item price plus additional charge",IF($S4="EXACT_COLLECTION_AMOUNT","Authorized amount breakdown required before settlement","Ready for collection and settlement")))))))))))) | AW4: =IF($AU4="","","PARCEL_FINANCIAL_V2")
L5: =IF($S5="","",IF($S5="ITEM_PRICE_PLUS_DECLARED_DELIVERY",IF(OR($J5="",$K5=""),"",SUM($J5,$K5,$U5)),IF($S5="TOTAL_AMOUNT_INCLUDING_DELIVERY",IF($T5="","",$T5),IF($S5="DELIVERY_CHARGE_ONLY",IF($K5="","",SUM($K5,$U5)),IF($S5="EXACT_COLLECTION_AMOUNT",IF($T5="","",$T5),IF($S5="ITEM_PRICE_ONLY_DELIVERY_PAID_BY_MERCHANT",IF($J5="","",SUM($J5,$U5)),"")))))) | AC5: =IFERROR(VLOOKUP($H5&"|"&$Q5,Tariff_Master!$A$2:$L$169,3,FALSE),"") | AD5: =IFERROR(VLOOKUP($H5&"|"&$Q5,Tariff_Master!$A$2:$L$169,4,FALSE),"") | AE5: =IFERROR(VLOOKUP($H5&"|"&$Q5,Tariff_Master!$A$2:$L$169,6,FALSE),"") | AF5: =IFERROR(VLOOKUP($H5&"|"&$Q5,Tariff_Master!$A$2:$L$169,7,FALSE),"") | AG5: =IFERROR(VLOOKUP($H5&"|"&$Q5,Tariff_Master!$A$2:$L$169,8,FALSE),"") | AH5: =IFERROR(VLOOKUP($H5&"|"&$Q5,Tariff_Master!$A$2:$L$169,9,FALSE),"") | AI5: =IFERROR(VLOOKUP($H5&"|"&$Q5,Tariff_Master!$A$2:$L$169,10,FALSE),"") | AJ5: =IF($M5="","",ROUNDUP(MAX(0,$M5),0)) | AK5: =IF(OR($AJ5="",$AF5=""),"",MAX(0,$AJ5-$AF5)) | AL5: =IF(OR($AK5="",$AG5=""),"",MAX(0,$AK5*$AG5)) | AM5: =IF($AE5="","",MAX(0,SUM($AE5,$AL5,$V5,$W5))) | AN5: =IF($AM5="","",IF(AND($Q5="COMMITMENT",$R5>=$AH5),$AI5,0)) | AO5: =IF($AM5="","",MAX(0,$AM5-$AN5)) | AP5: =IF($S5="","",IF(OR($S5="ITEM_PRICE_PLUS_DECLARED_DELIVERY",$S5="DELIVERY_CHARGE_ONLY"),$K5,IF($S5="TOTAL_AMOUNT_INCLUDING_DELIVERY",IF(OR($T5="",$J5=""),"",MAX(0,$T5-$J5-$U5)),IF($S5="ITEM_PRICE_ONLY_DELIVERY_PAID_BY_MERCHANT",0,"")))) | AQ5: =IF(OR($AP5="",$AO5=""),"",$AP5-$AO5) | AR5: =IF($S5="EXACT_COLLECTION_AMOUNT","BREAKDOWN_REQUIRED",IF($AQ5="","",IF($AQ5>0,"CREDIT_TO_MERCHANT",IF($AQ5<0,"DEDUCT_FROM_MERCHANT","NO_ADJUSTMENT")))) | AS5: =IF(OR($AQ5="",$AR5="BREAKDOWN_REQUIRED"),"",$AQ5) | AT5: =IF(OR($AR5="",$AR5="BREAKDOWN_REQUIRED"),"",SUM($J5,$AQ5,$Y5)-$X5) | AU5: =IF(AND($A5="",$B5="",$F5="",$H5="",$J5="",$K5="",$M5="",$S5=""),"",IF(OR($H5="",$Q5="",$M5="",$S5=""),"ERROR",IF(OR($J5<0,$K5<0,$M5<0,$T5<0,$U5<0,$V5<0,$W5<0,$X5<0,$Y5<0),"ERROR",IF($AE5="","ERROR",IF(AND(OR($S5="ITEM_PRICE_PLUS_DECLARED_DELIVERY",$S5="TOTAL_AMOUNT_INCLUDING_DELIVERY",$S5="ITEM_PRICE_ONLY_DELIVERY_PAID_BY_MERCHANT"),$J5=""),"ERROR",IF(AND(OR($S5="ITEM_PRICE_PLUS_DECLARED_DELIVERY",$S5="DELIVERY_CHARGE_ONLY"),$K5=""),"ERROR",IF(AND(OR($S5="TOTAL_AMOUNT_INCLUDING_DELIVERY",$S5="EXACT_COLLECTION_AMOUNT"),$T5=""),"ERROR",IF(AND($S5="TOTAL_AMOUNT_INCLUDING_DELIVERY",$T5<SUM($J5,$U5)),"ERROR",IF($S5="EXACT_COLLECTION_AMOUNT","REVIEW","OK"))))))))) | AV5: =IF($AU5="","",IF($H5="","Township required",IF($Q5="","Customer tier required",IF($M5="","Weight required",IF($S5="","Amount entry type required",IF(OR($J5<0,$K5<0,$M5<0,$T5<0,$U5<0,$V5<0,$W5<0,$X5<0,$Y5<0),"Negative amounts are not allowed",IF($AE5="","Tariff not found for township and tier",IF(AND(OR($S5="ITEM_PRICE_PLUS_DECLARED_DELIVERY",$S5="TOTAL_AMOUNT_INCLUDING_DELIVERY",$S5="ITEM_PRICE_ONLY_DELIVERY_PAID_BY_MERCHANT"),$J5=""),"Item price required for this amount type",IF(AND(OR($S5="ITEM_PRICE_PLUS_DECLARED_DELIVERY",$S5="DELIVERY_CHARGE_ONLY"),$K5=""),"Declared delivery charge required",IF(AND(OR($S5="TOTAL_AMOUNT_INCLUDING_DELIVERY",$S5="EXACT_COLLECTION_AMOUNT"),$T5=""),"Stated total amount required",IF(AND($S5="TOTAL_AMOUNT_INCLUDING_DELIVERY",$T5<SUM($J5,$U5)),"Stated total is below item price plus additional charge",IF($S5="EXACT_COLLECTION_AMOUNT","Authorized amount breakdown required before settlement","Ready for collection and settlement")))))))))))) | AW5: =IF($AU5="","","PARCEL_FINANCIAL_V2")
L6: =IF($S6="","",IF($S6="ITEM_PRICE_PLUS_DECLARED_DELIVERY",IF(OR($J6="",$K6=""),"",SUM($J6,$K6,$U6)),IF($S6="TOTAL_AMOUNT_INCLUDING_DELIVERY",IF($T6="","",$T6),IF($S6="DELIVERY_CHARGE_ONLY",IF($K6="","",SUM($K6,$U6)),IF($S6="EXACT_COLLECTION_AMOUNT",IF($T6="","",$T6),IF($S6="ITEM_PRICE_ONLY_DELIVERY_PAID_BY_MERCHANT",IF($J6="","",SUM($J6,$U6)),"")))))) | AC6: =IFERROR(VLOOKUP($H6&"|"&$Q6,Tariff_Master!$A$2:$L$169,3,FALSE),"") | AD6: =IFERROR(VLOOKUP($H6&"|"&$Q6,Tariff_Master!$A$2:$L$169,4,FALSE),"") | AE6: =IFERROR(VLOOKUP($H6&"|"&$Q6,Tariff_Master!$A$2:$L$169,6,FALSE),"") | AF6: =IFERROR(VLOOKUP($H6&"|"&$Q6,Tariff_Master!$A$2:$L$169,7,FALSE),"") | AG6: =IFERROR(VLOOKUP($H6&"|"&$Q6,Tariff_Master!$A$2:$L$169,8,FALSE),"") | AH6: =IFERROR(VLOOKUP($H6&"|"&$Q6,Tariff_Master!$A$2:$L$169,9,FALSE),"") | AI6: =IFERROR(VLOOKUP($H6&"|"&$Q6,Tariff_Master!$A$2:$L$169,10,FALSE),"") | AJ6: =IF($M6="","",ROUNDUP(MAX(0,$M6),0)) | AK6: =IF(OR($AJ6="",$AF6=""),"",MAX(0,$AJ6-$AF6)) | AL6: =IF(OR($AK6="",$AG6=""),"",MAX(0,$AK6*$AG6)) | AM6: =IF($AE6="","",MAX(0,SUM($AE6,$AL6,$V6,$W6))) | AN6: =IF($AM6="","",IF(AND($Q6="COMMITMENT",$R6>=$AH6),$AI6,0)) | AO6: =IF($AM6="","",MAX(0,$AM6-$AN6)) | AP6: =IF($S6="","",IF(OR($S6="ITEM_PRICE_PLUS_DECLARED_DELIVERY",$S6="DELIVERY_CHARGE_ONLY"),$K6,IF($S6="TOTAL_AMOUNT_INCLUDING_DELIVERY",IF(OR($T6="",$J6=""),"",MAX(0,$T6-$J6-$U6)),IF($S6="ITEM_PRICE_ONLY_DELIVERY_PAID_BY_MERCHANT",0,"")))) | AQ6: =IF(OR($AP6="",$AO6=""),"",$AP6-$AO6) | AR6: =IF($S6="EXACT_COLLECTION_AMOUNT","BREAKDOWN_REQUIRED",IF($AQ6="","",IF($AQ6>0,"CREDIT_TO_MERCHANT",IF($AQ6<0,"DEDUCT_FROM_MERCHANT","NO_ADJUSTMENT")))) | AS6: =IF(OR($AQ6="",$AR6="BREAKDOWN_REQUIRED"),"",$AQ6) | AT6: =IF(OR($AR6="",$AR6="BREAKDOWN_REQUIRED"),"",SUM($J6,$AQ6,$Y6)-$X6) | AU6: =IF(AND($A6="",$B6="",$F6="",$H6="",$J6="",$K6="",$M6="",$S6=""),"",IF(OR($H6="",$Q6="",$M6="",$S6=""),"ERROR",IF(OR($J6<0,$K6<0,$M6<0,$T6<0,$U6<0,$V6<0,$W6<0,$X6<0,$Y6<0),"ERROR",IF($AE6="","ERROR",IF(AND(OR($S6="ITEM_PRICE_PLUS_DECLARED_DELIVERY",$S6="TOTAL_AMOUNT_INCLUDING_DELIVERY",$S6="ITEM_PRICE_ONLY_DELIVERY_PAID_BY_MERCHANT"),$J6=""),"ERROR",IF(AND(OR($S6="ITEM_PRICE_PLUS_DECLARED_DELIVERY",$S6="DELIVERY_CHARGE_ONLY"),$K6=""),"ERROR",IF(AND(OR($S6="TOTAL_AMOUNT_INCLUDING_DELIVERY",$S6="EXACT_COLLECTION_AMOUNT"),$T6=""),"ERROR",IF(AND($S6="TOTAL_AMOUNT_INCLUDING_DELIVERY",$T6<SUM($J6,$U6)),"ERROR",IF($S6="EXACT_COLLECTION_AMOUNT","REVIEW","OK"))))))))) | AV6: =IF($AU6="","",IF($H6="","Township required",IF($Q6="","Customer tier required",IF($M6="","Weight required",IF($S6="","Amount entry type required",IF(OR($J6<0,$K6<0,$M6<0,$T6<0,$U6<0,$V6<0,$W6<0,$X6<0,$Y6<0),"Negative amounts are not allowed",IF($AE6="","Tariff not found for township and tier",IF(AND(OR($S6="ITEM_PRICE_PLUS_DECLARED_DELIVERY",$S6="TOTAL_AMOUNT_INCLUDING_DELIVERY",$S6="ITEM_PRICE_ONLY_DELIVERY_PAID_BY_MERCHANT"),$J6=""),"Item price required for this amount type",IF(AND(OR($S6="ITEM_PRICE_PLUS_DECLARED_DELIVERY",$S6="DELIVERY_CHARGE_ONLY"),$K6=""),"Declared delivery charge required",IF(AND(OR($S6="TOTAL_AMOUNT_INCLUDING_DELIVERY",$S6="EXACT_COLLECTION_AMOUNT"),$T6=""),"Stated total amount required",IF(AND($S6="TOTAL_AMOUNT_INCLUDING_DELIVERY",$T6<SUM($J6,$U6)),"Stated total is below item price plus additional charge",IF($S6="EXACT_COLLECTION_AMOUNT","Authorized amount breakdown required before settlement","Ready for collection and settlement")))))))))))) | AW6: =IF($AU6="","","PARCEL_FINANCIAL_V2")
L7: =IF($S7="","",IF($S7="ITEM_PRICE_PLUS_DECLARED_DELIVERY",IF(OR($J7="",$K7=""),"",SUM($J7,$K7,$U7)),IF($S7="TOTAL_AMOUNT_INCLUDING_DELIVERY",IF($T7="","",$T7),IF($S7="DELIVERY_CHARGE_ONLY",IF($K7="","",SUM($K7,$U7)),IF($S7="EXACT_COLLECTION_AMOUNT",IF($T7="","",$T7),IF($S7="ITEM_PRICE_ONLY_DELIVERY_PAID_BY_MERCHANT",IF($J7="","",SUM($J7,$U7)),"")))))) | AC7: =IFERROR(VLOOKUP($H7&"|"&$Q7,Tariff_Master!$A$2:$L$169,3,FALSE),"") | AD7: =IFERROR(VLOOKUP($H7&"|"&$Q7,Tariff_Master!$A$2:$L$169,4,FALSE),"") | AE7: =IFERROR(VLOOKUP($H7&"|"&$Q7,Tariff_Master!$A$2:$L$169,6,FALSE),"") | AF7: =IFERROR(VLOOKUP($H7&"|"&$Q7,Tariff_Master!$A$2:$L$169,7,FALSE),"") | AG7: =IFERROR(VLOOKUP($H7&"|"&$Q7,Tariff_Master!$A$2:$L$169,8,FALSE),"") | AH7: =IFERROR(VLOOKUP($H7&"|"&$Q7,Tariff_Master!$A$2:$L$169,9,FALSE),"") | AI7: =IFERROR(VLOOKUP($H7&"|"&$Q7,Tariff_Master!$A$2:$L$169,10,FALSE),"") | AJ7: =IF($M7="","",ROUNDUP(MAX(0,$M7),0)) | AK7: =IF(OR($AJ7="",$AF7=""),"",MAX(0,$AJ7-$AF7)) | AL7: =IF(OR($AK7="",$AG7=""),"",MAX(0,$AK7*$AG7)) | AM7: =IF($AE7="","",MAX(0,SUM($AE7,$AL7,$V7,$W7))) | AN7: =IF($AM7="","",IF(AND($Q7="COMMITMENT",$R7>=$AH7),$AI7,0)) | AO7: =IF($AM7="","",MAX(0,$AM7-$AN7)) | AP7: =IF($S7="","",IF(OR($S7="ITEM_PRICE_PLUS_DECLARED_DELIVERY",$S7="DELIVERY_CHARGE_ONLY"),$K7,IF($S7="TOTAL_AMOUNT_INCLUDING_DELIVERY",IF(OR($T7="",$J7=""),"",MAX(0,$T7-$J7-$U7)),IF($S7="ITEM_PRICE_ONLY_DELIVERY_PAID_BY_MERCHANT",0,"")))) | AQ7: =IF(OR($AP7="",$AO7=""),"",$AP7-$AO7) | AR7: =IF($S7="EXACT_COLLECTION_AMOUNT","BREAKDOWN_REQUIRED",IF($AQ7="","",IF($AQ7>0,"CREDIT_TO_MERCHANT",IF($AQ7<0,"DEDUCT_FROM_MERCHANT","NO_ADJUSTMENT")))) | AS7: =IF(OR($AQ7="",$AR7="BREAKDOWN_REQUIRED"),"",$AQ7) | AT7: =IF(OR($AR7="",$AR7="BREAKDOWN_REQUIRED"),"",SUM($J7,$AQ7,$Y7)-$X7) | AU7: =IF(AND($A7="",$B7="",$F7="",$H7="",$J7="",$K7="",$M7="",$S7=""),"",IF(OR($H7="",$Q7="",$M7="",$S7=""),"ERROR",IF(OR($J7<0,$K7<0,$M7<0,$T7<0,$U7<0,$V7<0,$W7<0,$X7<0,$Y7<0),"ERROR",IF($AE7="","ERROR",IF(AND(OR($S7="ITEM_PRICE_PLUS_DECLARED_DELIVERY",$S7="TOTAL_AMOUNT_INCLUDING_DELIVERY",$S7="ITEM_PRICE_ONLY_DELIVERY_PAID_BY_MERCHANT"),$J7=""),"ERROR",IF(AND(OR($S7="ITEM_PRICE_PLUS_DECLARED_DELIVERY",$S7="DELIVERY_CHARGE_ONLY"),$K7=""),"ERROR",IF(AND(OR($S7="TOTAL_AMOUNT_INCLUDING_DELIVERY",$S7="EXACT_COLLECTION_AMOUNT"),$T7=""),"ERROR",IF(AND($S7="TOTAL_AMOUNT_INCLUDING_DELIVERY",$T7<SUM($J7,$U7)),"ERROR",IF($S7="EXACT_COLLECTION_AMOUNT","REVIEW","OK"))))))))) | AV7: =IF($AU7="","",IF($H7="","Township required",IF($Q7="","Customer tier required",IF($M7="","Weight required",IF($S7="","Amount entry type required",IF(OR($J7<0,$K7<0,$M7<0,$T7<0,$U7<0,$V7<0,$W7<0,$X7<0,$Y7<0),"Negative amounts are not allowed",IF($AE7="","Tariff not found for township and tier",IF(AND(OR($S7="ITEM_PRICE_PLUS_DECLARED_DELIVERY",$S7="TOTAL_AMOUNT_INCLUDING_DELIVERY",$S7="ITEM_PRICE_ONLY_DELIVERY_PAID_BY_MERCHANT"),$J7=""),"Item price required for this amount type",IF(AND(OR($S7="ITEM_PRICE_PLUS_DECLARED_DELIVERY",$S7="DELIVERY_CHARGE_ONLY"),$K7=""),"Declared delivery charge required",IF(AND(OR($S7="TOTAL_AMOUNT_INCLUDING_DELIVERY",$S7="EXACT_COLLECTION_AMOUNT"),$T7=""),"Stated total amount required",IF(AND($S7="TOTAL_AMOUNT_INCLUDING_DELIVERY",$T7<SUM($J7,$U7)),"Stated total is below item price plus additional charge",IF($S7="EXACT_COLLECTION_AMOUNT","Authorized amount breakdown required before settlement","Ready for collection and settlement")))))))))))) | AW7: =IF($AU7="","","PARCEL_FINANCIAL_V2")
L8: =IF($S8="","",IF($S8="ITEM_PRICE_PLUS_DECLARED_DELIVERY",IF(OR($J8="",$K8=""),"",SUM($J8,$K8,$U8)),IF($S8="TOTAL_AMOUNT_INCLUDING_DELIVERY",IF($T8="","",$T8),IF($S8="DELIVERY_CHARGE_ONLY",IF($K8="","",SUM($K8,$U8)),IF($S8="EXACT_COLLECTION_AMOUNT",IF($T8="","",$T8),IF($S8="ITEM_PRICE_ONLY_DELIVERY_PAID_BY_MERCHANT",IF($J8="","",SUM($J8,$U8)),"")))))) | AC8: =IFERROR(VLOOKUP($H8&"|"&$Q8,Tariff_Master!$A$2:$L$169,3,FALSE),"") | AD8: =IFERROR(VLOOKUP($H8&"|"&$Q8,Tariff_Master!$A$2:$L$169,4,FALSE),"") | AE8: =IFERROR(VLOOKUP($H8&"|"&$Q8,Tariff_Master!$A$2:$L$169,6,FALSE),"") | AF8: =IFERROR(VLOOKUP($H8&"|"&$Q8,Tariff_Master!$A$2:$L$169,7,FALSE),"") | AG8: =IFERROR(VLOOKUP($H8&"|"&$Q8,Tariff_Master!$A$2:$L$169,8,FALSE),"") | AH8: =IFERROR(VLOOKUP($H8&"|"&$Q8,Tariff_Master!$A$2:$L$169,9,FALSE),"") | AI8: =IFERROR(VLOOKUP($H8&"|"&$Q8,Tariff_Master!$A$2:$L$169,10,FALSE),"") | AJ8: =IF($M8="","",ROUNDUP(MAX(0,$M8),0)) | AK8: =IF(OR($AJ8="",$AF8=""),"",MAX(0,$AJ8-$AF8)) | AL8: =IF(OR($AK8="",$AG8=""),"",MAX(0,$AK8*$AG8)) | AM8: =IF($AE8="","",MAX(0,SUM($AE8,$AL8,$V8,$W8))) | AN8: =IF($AM8="","",IF(AND($Q8="COMMITMENT",$R8>=$AH8),$AI8,0)) | AO8: =IF($AM8="","",MAX(0,$AM8-$AN8)) | AP8: =IF($S8="","",IF(OR($S8="ITEM_PRICE_PLUS_DECLARED_DELIVERY",$S8="DELIVERY_CHARGE_ONLY"),$K8,IF($S8="TOTAL_AMOUNT_INCLUDING_DELIVERY",IF(OR($T8="",$J8=""),"",MAX(0,$T8-$J8-$U8)),IF($S8="ITEM_PRICE_ONLY_DELIVERY_PAID_BY_MERCHANT",0,"")))) | AQ8: =IF(OR($AP8="",$AO8=""),"",$AP8-$AO8) | AR8: =IF($S8="EXACT_COLLECTION_AMOUNT","BREAKDOWN_REQUIRED",IF($AQ8="","",IF($AQ8>0,"CREDIT_TO_MERCHANT",IF($AQ8<0,"DEDUCT_FROM_MERCHANT","NO_ADJUSTMENT")))) | AS8: =IF(OR($AQ8="",$AR8="BREAKDOWN_REQUIRED"),"",$AQ8) | AT8: =IF(OR($AR8="",$AR8="BREAKDOWN_REQUIRED"),"",SUM($J8,$AQ8,$Y8)-$X8) | AU8: =IF(AND($A8="",$B8="",$F8="",$H8="",$J8="",$K8="",$M8="",$S8=""),"",IF(OR($H8="",$Q8="",$M8="",$S8=""),"ERROR",IF(OR($J8<0,$K8<0,$M8<0,$T8<0,$U8<0,$V8<0,$W8<0,$X8<0,$Y8<0),"ERROR",IF($AE8="","ERROR",IF(AND(OR($S8="ITEM_PRICE_PLUS_DECLARED_DELIVERY",$S8="TOTAL_AMOUNT_INCLUDING_DELIVERY",$S8="ITEM_PRICE_ONLY_DELIVERY_PAID_BY_MERCHANT"),$J8=""),"ERROR",IF(AND(OR($S8="ITEM_PRICE_PLUS_DECLARED_DELIVERY",$S8="DELIVERY_CHARGE_ONLY"),$K8=""),"ERROR",IF(AND(OR($S8="TOTAL_AMOUNT_INCLUDING_DELIVERY",$S8="EXACT_COLLECTION_AMOUNT"),$T8=""),"ERROR",IF(AND($S8="TOTAL_AMOUNT_INCLUDING_DELIVERY",$T8<SUM($J8,$U8)),"ERROR",IF($S8="EXACT_COLLECTION_AMOUNT","REVIEW","OK"))))))))) | AV8: =IF($AU8="","",IF($H8="","Township required",IF($Q8="","Customer tier required",IF($M8="","Weight required",IF($S8="","Amount entry type required",IF(OR($J8<0,$K8<0,$M8<0,$T8<0,$U8<0,$V8<0,$W8<0,$X8<0,$Y8<0),"Negative amounts are not allowed",IF($AE8="","Tariff not found for township and tier",IF(AND(OR($S8="ITEM_PRICE_PLUS_DECLARED_DELIVERY",$S8="TOTAL_AMOUNT_INCLUDING_DELIVERY",$S8="ITEM_PRICE_ONLY_DELIVERY_PAID_BY_MERCHANT"),$J8=""),"Item price required for this amount type",IF(AND(OR($S8="ITEM_PRICE_PLUS_DECLARED_DELIVERY",$S8="DELIVERY_CHARGE_ONLY"),$K8=""),"Declared delivery charge required",IF(AND(OR($S8="TOTAL_AMOUNT_INCLUDING_DELIVERY",$S8="EXACT_COLLECTION_AMOUNT"),$T8=""),"Stated total amount required",IF(AND($S8="TOTAL_AMOUNT_INCLUDING_DELIVERY",$T8<SUM($J8,$U8)),"Stated total is below item price plus additional charge",IF($S8="EXACT_COLLECTION_AMOUNT","Authorized amount breakdown required before settlement","Ready for collection and settlement")))))))))))) | AW8: =IF($AU8="","","PARCEL_FINANCIAL_V2")
L9: =IF($S9="","",IF($S9="ITEM_PRICE_PLUS_DECLARED_DELIVERY",IF(OR($J9="",$K9=""),"",SUM($J9,$K9,$U9)),IF($S9="TOTAL_AMOUNT_INCLUDING_DELIVERY",IF($T9="","",$T9),IF($S9="DELIVERY_CHARGE_ONLY",IF($K9="","",SUM($K9,$U9)),IF($S9="EXACT_COLLECTION_AMOUNT",IF($T9="","",$T9),IF($S9="ITEM_PRICE_ONLY_DELIVERY_PAID_BY_MERCHANT",IF($J9="","",SUM($J9,$U9)),"")))))) | AC9: =IFERROR(VLOOKUP($H9&"|"&$Q9,Tariff_Master!$A$2:$L$169,3,FALSE),"") | AD9: =IFERROR(VLOOKUP($H9&"|"&$Q9,Tariff_Master!$A$2:$L$169,4,FALSE),"") | AE9: =IFERROR(VLOOKUP($H9&"|"&$Q9,Tariff_Master!$A$2:$L$169,6,FALSE),"") | AF9: =IFERROR(VLOOKUP($H9&"|"&$Q9,Tariff_Master!$A$2:$L$169,7,FALSE),"") | AG9: =IFERROR(VLOOKUP($H9&"|"&$Q9,Tariff_Master!$A$2:$L$169,8,FALSE),"") | AH9: =IFERROR(VLOOKUP($H9&"|"&$Q9,Tariff_Master!$A$2:$L$169,9,FALSE),"") | AI9: =IFERROR(VLOOKUP($H9&"|"&$Q9,Tariff_Master!$A$2:$L$169,10,FALSE),"") | AJ9: =IF($M9="","",ROUNDUP(MAX(0,$M9),0)) | AK9: =IF(OR($AJ9="",$AF9=""),"",MAX(0,$AJ9-$AF9)) | AL9: =IF(OR($AK9="",$AG9=""),"",MAX(0,$AK9*$AG9)) | AM9: =IF($AE9="","",MAX(0,SUM($AE9,$AL9,$V9,$W9))) | AN9: =IF($AM9="","",IF(AND($Q9="COMMITMENT",$R9>=$AH9),$AI9,0)) | AO9: =IF($AM9="","",MAX(0,$AM9-$AN9)) | AP9: =IF($S9="","",IF(OR($S9="ITEM_PRICE_PLUS_DECLARED_DELIVERY",$S9="DELIVERY_CHARGE_ONLY"),$K9,IF($S9="TOTAL_AMOUNT_INCLUDING_DELIVERY",IF(OR($T9="",$J9=""),"",MAX(0,$T9-$J9-$U9)),IF($S9="ITEM_PRICE_ONLY_DELIVERY_PAID_BY_MERCHANT",0,"")))) | AQ9: =IF(OR($AP9="",$AO9=""),"",$AP9-$AO9) | AR9: =IF($S9="EXACT_COLLECTION_AMOUNT","BREAKDOWN_REQUIRED",IF($AQ9="","",IF($AQ9>0,"CREDIT_TO_MERCHANT",IF($AQ9<0,"DEDUCT_FROM_MERCHANT","NO_ADJUSTMENT")))) | AS9: =IF(OR($AQ9="",$AR9="BREAKDOWN_REQUIRED"),"",$AQ9) | AT9: =IF(OR($AR9="",$AR9="BREAKDOWN_REQUIRED"),"",SUM($J9,$AQ9,$Y9)-$X9) | AU9: =IF(AND($A9="",$B9="",$F9="",$H9="",$J9="",$K9="",$M9="",$S9=""),"",IF(OR($H9="",$Q9="",$M9="",$S9=""),"ERROR",IF(OR($J9<0,$K9<0,$M9<0,$T9<0,$U9<0,$V9<0,$W9<0,$X9<0,$Y9<0),"ERROR",IF($AE9="","ERROR",IF(AND(OR($S9="ITEM_PRICE_PLUS_DECLARED_DELIVERY",$S9="TOTAL_AMOUNT_INCLUDING_DELIVERY",$S9="ITEM_PRICE_ONLY_DELIVERY_PAID_BY_MERCHANT"),$J9=""),"ERROR",IF(AND(OR($S9="ITEM_PRICE_PLUS_DECLARED_DELIVERY",$S9="DELIVERY_CHARGE_ONLY"),$K9=""),"ERROR",IF(AND(OR($S9="TOTAL_AMOUNT_INCLUDING_DELIVERY",$S9="EXACT_COLLECTION_AMOUNT"),$T9=""),"ERROR",IF(AND($S9="TOTAL_AMOUNT_INCLUDING_DELIVERY",$T9<SUM($J9,$U9)),"ERROR",IF($S9="EXACT_COLLECTION_AMOUNT","REVIEW","OK"))))))))) | AV9: =IF($AU9="","",IF($H9="","Township required",IF($Q9="","Customer tier required",IF($M9="","Weight required",IF($S9="","Amount entry type required",IF(OR($J9<0,$K9<0,$M9<0,$T9<0,$U9<0,$V9<0,$W9<0,$X9<0,$Y9<0),"Negative amounts are not allowed",IF($AE9="","Tariff not found for township and tier",IF(AND(OR($S9="ITEM_PRICE_PLUS_DECLARED_DELIVERY",$S9="TOTAL_AMOUNT_INCLUDING_DELIVERY",$S9="ITEM_PRICE_ONLY_DELIVERY_PAID_BY_MERCHANT"),$J9=""),"Item price required for this amount type",IF(AND(OR($S9="ITEM_PRICE_PLUS_DECLARED_DELIVERY",$S9="DELIVERY_CHARGE_ONLY"),$K9=""),"Declared delivery charge required",IF(AND(OR($S9="TOTAL_AMOUNT_INCLUDING_DELIVERY",$S9="EXACT_COLLECTION_AMOUNT"),$T9=""),"Stated total amount required",IF(AND($S9="TOTAL_AMOUNT_INCLUDING_DELIVERY",$T9<SUM($J9,$U9)),"Stated total is below item price plus additional charge",IF($S9="EXACT_COLLECTION_AMOUNT","Authorized amount breakdown required before settlement","Ready for collection and settlement")))))))))))) | AW9: =IF($AU9="","","PARCEL_FINANCIAL_V2")
L10: =IF($S10="","",IF($S10="ITEM_PRICE_PLUS_DECLARED_DELIVERY",IF(OR($J10="",$K10=""),"",SUM($J10,$K10,$U10)),IF($S10="TOTAL_AMOUNT_INCLUDING_DELIVERY",IF($T10="","",$T10),IF($S10="DELIVERY_CHARGE_ONLY",IF($K10="","",SUM($K10,$U10)),IF($S10="EXACT_COLLECTION_AMOUNT",IF($T10="","",$T10),IF($S10="ITEM_PRICE_ONLY_DELIVERY_PAID_BY_MERCHANT",IF($J10="","",SUM($J10,$U10)),"")))))) | AC10: =IFERROR(VLOOKUP($H10&"|"&$Q10,Tariff_Master!$A$2:$L$169,3,FALSE),"") | AD10: =IFERROR(VLOOKUP($H10&"|"&$Q10,Tariff_Master!$A$2:$L$169,4,FALSE),"") | AE10: =IFERROR(VLOOKUP($H10&"|"&$Q10,Tariff_Master!$A$2:$L$169,6,FALSE),"") | AF10: =IFERROR(VLOOKUP($H10&"|"&$Q10,Tariff_Master!$A$2:$L$169,7,FALSE),"") | AG10: =IFERROR(VLOOKUP($H10&"|"&$Q10,Tariff_Master!$A$2:$L$169,8,FALSE),"") | AH10: =IFERROR(VLOOKUP($H10&"|"&$Q10,Tariff_Master!$A$2:$L$169,9,FALSE),"") | AI10: =IFERROR(VLOOKUP($H10&"|"&$Q10,Tariff_Master!$A$2:$L$169,10,FALSE),"") | AJ10: =IF($M10="","",ROUNDUP(MAX(0,$M10),0)) | AK10: =IF(OR($AJ10="",$AF10=""),"",MAX(0,$AJ10-$AF10)) | AL10: =IF(OR($AK10="",$AG10=""),"",MAX(0,$AK10*$AG10)) | AM10: =IF($AE10="","",MAX(0,SUM($AE10,$AL10,$V10,$W10))) | AN10: =IF($AM10="","",IF(AND($Q10="COMMITMENT",$R10>=$AH10),$AI10,0)) | AO10: =IF($AM10="","",MAX(0,$AM10-$AN10)) | AP10: =IF($S10="","",IF(OR($S10="ITEM_PRICE_PLUS_DECLARED_DELIVERY",$S10="DELIVERY_CHARGE_ONLY"),$K10,IF($S10="TOTAL_AMOUNT_INCLUDING_DELIVERY",IF(OR($T10="",$J10=""),"",MAX(0,$T10-$J10-$U10)),IF($S10="ITEM_PRICE_ONLY_DELIVERY_PAID_BY_MERCHANT",0,"")))) | AQ10: =IF(OR($AP10="",$AO10=""),"",$AP10-$AO10) | AR10: =IF($S10="EXACT_COLLECTION_AMOUNT","BREAKDOWN_REQUIRED",IF($AQ10="","",IF($AQ10>0,"CREDIT_TO_MERCHANT",IF($AQ10<0,"DEDUCT_FROM_MERCHANT","NO_ADJUSTMENT")))) | AS10: =IF(OR($AQ10="",$AR10="BREAKDOWN_REQUIRED"),"",$AQ10) | AT10: =IF(OR($AR10="",$AR10="BREAKDOWN_REQUIRED"),"",SUM($J10,$AQ10,$Y10)-$X10) | AU10: =IF(AND($A10="",$B10="",$F10="",$H10="",$J10="",$K10="",$M10="",$S10=""),"",IF(OR($H10="",$Q10="",$M10="",$S10=""),"ERROR",IF(OR($J10<0,$K10<0,$M10<0,$T10<0,$U10<0,$V10<0,$W10<0,$X10<0,$Y10<0),"ERROR",IF($AE10="","ERROR",IF(AND(OR($S10="ITEM_PRICE_PLUS_DECLARED_DELIVERY",$S10="TOTAL_AMOUNT_INCLUDING_DELIVERY",$S10="ITEM_PRICE_ONLY_DELIVERY_PAID_BY_MERCHANT"),$J10=""),"ERROR",IF(AND(OR($S10="ITEM_PRICE_PLUS_DECLARED_DELIVERY",$S10="DELIVERY_CHARGE_ONLY"),$K10=""),"ERROR",IF(AND(OR($S10="TOTAL_AMOUNT_INCLUDING_DELIVERY",$S10="EXACT_COLLECTION_AMOUNT"),$T10=""),"ERROR",IF(AND($S10="TOTAL_AMOUNT_INCLUDING_DELIVERY",$T10<SUM($J10,$U10)),"ERROR",IF($S10="EXACT_COLLECTION_AMOUNT","REVIEW","OK"))))))))) | AV10: =IF($AU10="","",IF($H10="","Township required",IF($Q10="","Customer tier required",IF($M10="","Weight required",IF($S10="","Amount entry type required",IF(OR($J10<0,$K10<0,$M10<0,$T10<0,$U10<0,$V10<0,$W10<0,$X10<0,$Y10<0),"Negative amounts are not allowed",IF($AE10="","Tariff not found for township and tier",IF(AND(OR($S10="ITEM_PRICE_PLUS_DECLARED_DELIVERY",$S10="TOTAL_AMOUNT_INCLUDING_DELIVERY",$S10="ITEM_PRICE_ONLY_DELIVERY_PAID_BY_MERCHANT"),$J10=""),"Item price required for this amount type",IF(AND(OR($S10="ITEM_PRICE_PLUS_DECLARED_DELIVERY",$S10="DELIVERY_CHARGE_ONLY"),$K10=""),"Declared delivery charge required",IF(AND(OR($S10="TOTAL_AMOUNT_INCLUDING_DELIVERY",$S10="EXACT_COLLECTION_AMOUNT"),$T10=""),"Stated total amount required",IF(AND($S10="TOTAL_AMOUNT_INCLUDING_DELIVERY",$T10<SUM($J10,$U10)),"Stated total is below item price plus additional charge",IF($S10="EXACT_COLLECTION_AMOUNT","Authorized amount breakdown required before settlement","Ready for collection and settlement")))))))))))) | AW10: =IF($AU10="","","PARCEL_FINANCIAL_V2")
L11: =IF($S11="","",IF($S11="ITEM_PRICE_PLUS_DECLARED_DELIVERY",IF(OR($J11="",$K11=""),"",SUM($J11,$K11,$U11)),IF($S11="TOTAL_AMOUNT_INCLUDING_DELIVERY",IF($T11="","",$T11),IF($S11="DELIVERY_CHARGE_ONLY",IF($K11="","",SUM($K11,$U11)),IF($S11="EXACT_COLLECTION_AMOUNT",IF($T11="","",$T11),IF($S11="ITEM_PRICE_ONLY_DELIVERY_PAID_BY_MERCHANT",IF($J11="","",SUM($J11,$U11)),"")))))) | AC11: =IFERROR(VLOOKUP($H11&"|"&$Q11,Tariff_Master!$A$2:$L$169,3,FALSE),"") | AD11: =IFERROR(VLOOKUP($H11&"|"&$Q11,Tariff_Master!$A$2:$L$169,4,FALSE),"") | AE11: =IFERROR(VLOOKUP($H11&"|"&$Q11,Tariff_Master!$A$2:$L$169,6,FALSE),"") | AF11: =IFERROR(VLOOKUP($H11&"|"&$Q11,Tariff_Master!$A$2:$L$169,7,FALSE),"") | AG11: =IFERROR(VLOOKUP($H11&"|"&$Q11,Tariff_Master!$A$2:$L$169,8,FALSE),"") | AH11: =IFERROR(VLOOKUP($H11&"|"&$Q11,Tariff_Master!$A$2:$L$169,9,FALSE),"") | AI11: =IFERROR(VLOOKUP($H11&"|"&$Q11,Tariff_Master!$A$2:$L$169,10,FALSE),"") | AJ11: =IF($M11="","",ROUNDUP(MAX(0,$M11),0)) | AK11: =IF(OR($AJ11="",$AF11=""),"",MAX(0,$AJ11-$AF11)) | AL11: =IF(OR($AK11="",$AG11=""),"",MAX(0,$AK11*$AG11)) | AM11: =IF($AE11="","",MAX(0,SUM($AE11,$AL11,$V11,$W11))) | AN11: =IF($AM11="","",IF(AND($Q11="COMMITMENT",$R11>=$AH11),$AI11,0)) | AO11: =IF($AM11="","",MAX(0,$AM11-$AN11)) | AP11: =IF($S11="","",IF(OR($S11="ITEM_PRICE_PLUS_DECLARED_DELIVERY",$S11="DELIVERY_CHARGE_ONLY"),$K11,IF($S11="TOTAL_AMOUNT_INCLUDING_DELIVERY",IF(OR($T11="",$J11=""),"",MAX(0,$T11-$J11-$U11)),IF($S11="ITEM_PRICE_ONLY_DELIVERY_PAID_BY_MERCHANT",0,"")))) | AQ11: =IF(OR($AP11="",$AO11=""),"",$AP11-$AO11) | AR11: =IF($S11="EXACT_COLLECTION_AMOUNT","BREAKDOWN_REQUIRED",IF($AQ11="","",IF($AQ11>0,"CREDIT_TO_MERCHANT",IF($AQ11<0,"DEDUCT_FROM_MERCHANT","NO_ADJUSTMENT")))) | AS11: =IF(OR($AQ11="",$AR11="BREAKDOWN_REQUIRED"),"",$AQ11) | AT11: =IF(OR($AR11="",$AR11="BREAKDOWN_REQUIRED"),"",SUM($J11,$AQ11,$Y11)-$X11) | AU11: =IF(AND($A11="",$B11="",$F11="",$H11="",$J11="",$K11="",$M11="",$S11=""),"",IF(OR($H11="",$Q11="",$M11="",$S11=""),"ERROR",IF(OR($J11<0,$K11<0,$M11<0,$T11<0,$U11<0,$V11<0,$W11<0,$X11<0,$Y11<0),"ERROR",IF($AE11="","ERROR",IF(AND(OR($S11="ITEM_PRICE_PLUS_DECLARED_DELIVERY",$S11="TOTAL_AMOUNT_INCLUDING_DELIVERY",$S11="ITEM_PRICE_ONLY_DELIVERY_PAID_BY_MERCHANT"),$J11=""),"ERROR",IF(AND(OR($S11="ITEM_PRICE_PLUS_DECLARED_DELIVERY",$S11="DELIVERY_CHARGE_ONLY"),$K11=""),"ERROR",IF(AND(OR($S11="TOTAL_AMOUNT_INCLUDING_DELIVERY",$S11="EXACT_COLLECTION_AMOUNT"),$T11=""),"ERROR",IF(AND($S11="TOTAL_AMOUNT_INCLUDING_DELIVERY",$T11<SUM($J11,$U11)),"ERROR",IF($S11="EXACT_COLLECTION_AMOUNT","REVIEW","OK"))))))))) | AV11: =IF($AU11="","",IF($H11="","Township required",IF($Q11="","Customer tier required",IF($M11="","Weight required",IF($S11="","Amount entry type required",IF(OR($J11<0,$K11<0,$M11<0,$T11<0,$U11<0,$V11<0,$W11<0,$X11<0,$Y11<0),"Negative amounts are not allowed",IF($AE11="","Tariff not found for township and tier",IF(AND(OR($S11="ITEM_PRICE_PLUS_DECLARED_DELIVERY",$S11="TOTAL_AMOUNT_INCLUDING_DELIVERY",$S11="ITEM_PRICE_ONLY_DELIVERY_PAID_BY_MERCHANT"),$J11=""),"Item price required for this amount type",IF(AND(OR($S11="ITEM_PRICE_PLUS_DECLARED_DELIVERY",$S11="DELIVERY_CHARGE_ONLY"),$K11=""),"Declared delivery charge required",IF(AND(OR($S11="TOTAL_AMOUNT_INCLUDING_DELIVERY",$S11="EXACT_COLLECTION_AMOUNT"),$T11=""),"Stated total amount required",IF(AND($S11="TOTAL_AMOUNT_INCLUDING_DELIVERY",$T11<SUM($J11,$U11)),"Stated total is below item price plus additional charge",IF($S11="EXACT_COLLECTION_AMOUNT","Authorized amount breakdown required before settlement","Ready for collection and settlement")))))))))))) | AW11: =IF($AU11="","","PARCEL_FINANCIAL_V2")
L12: =IF($S12="","",IF($S12="ITEM_PRICE_PLUS_DECLARED_DELIVERY",IF(OR($J12="",$K12=""),"",SUM($J12,$K12,$U12)),IF($S12="TOTAL_AMOUNT_INCLUDING_DELIVERY",IF($T12="","",$T12),IF($S12="DELIVERY_CHARGE_ONLY",IF($K12="","",SUM($K12,$U12)),IF($S12="EXACT_COLLECTION_AMOUNT",IF($T12="","",$T12),IF($S12="ITEM_PRICE_ONLY_DELIVERY_PAID_BY_MERCHANT",IF($J12="","",SUM($J12,$U12)),"")))))) | AC12: =IFERROR(VLOOKUP($H12&"|"&$Q12,Tariff_Master!$A$2:$L$169,3,FALSE),"") | AD12: =IFERROR(VLOOKUP($H12&"|"&$Q12,Tariff_Master!$A$2:$L$169,4,FALSE),"") | AE12: =IFERROR(VLOOKUP($H12&"|"&$Q12,Tariff_Master!$A$2:$L$169,6,FALSE),"") | AF12: =IFERROR(VLOOKUP($H12&"|"&$Q12,Tariff_Master!$A$2:$L$169,7,FALSE),"") | AG12: =IFERROR(VLOOKUP($H12&"|"&$Q12,Tariff_Master!$A$2:$L$169,8,FALSE),"") | AH12: =IFERROR(VLOOKUP($H12&"|"&$Q12,Tariff_Master!$A$2:$L$169,9,FALSE),"") | AI12: =IFERROR(VLOOKUP($H12&"|"&$Q12,Tariff_Master!$A$2:$L$169,10,FALSE),"") | AJ12: =IF($M12="","",ROUNDUP(MAX(0,$M12),0)) | AK12: =IF(OR($AJ12="",$AF12=""),"",MAX(0,$AJ12-$AF12)) | AL12: =IF(OR($AK12="",$AG12=""),"",MAX(0,$AK12*$AG12)) | AM12: =IF($AE12="","",MAX(0,SUM($AE12,$AL12,$V12,$W12))) | AN12: =IF($AM12="","",IF(AND($Q12="COMMITMENT",$R12>=$AH12),$AI12,0)) | AO12: =IF($AM12="","",MAX(0,$AM12-$AN12)) | AP12: =IF($S12="","",IF(OR($S12="ITEM_PRICE_PLUS_DECLARED_DELIVERY",$S12="DELIVERY_CHARGE_ONLY"),$K12,IF($S12="TOTAL_AMOUNT_INCLUDING_DELIVERY",IF(OR($T12="",$J12=""),"",MAX(0,$T12-$J12-$U12)),IF($S12="ITEM_PRICE_ONLY_DELIVERY_PAID_BY_MERCHANT",0,"")))) | AQ12: =IF(OR($AP12="",$AO12=""),"",$AP12-$AO12) | AR12: =IF($S12="EXACT_COLLECTION_AMOUNT","BREAKDOWN_REQUIRED",IF($AQ12="","",IF($AQ12>0,"CREDIT_TO_MERCHANT",IF($AQ12<0,"DEDUCT_FROM_MERCHANT","NO_ADJUSTMENT")))) | AS12: =IF(OR($AQ12="",$AR12="BREAKDOWN_REQUIRED"),"",$AQ12) | AT12: =IF(OR($AR12="",$AR12="BREAKDOWN_REQUIRED"),"",SUM($J12,$AQ12,$Y12)-$X12) | AU12: =IF(AND($A12="",$B12="",$F12="",$H12="",$J12="",$K12="",$M12="",$S12=""),"",IF(OR($H12="",$Q12="",$M12="",$S12=""),"ERROR",IF(OR($J12<0,$K12<0,$M12<0,$T12<0,$U12<0,$V12<0,$W12<0,$X12<0,$Y12<0),"ERROR",IF($AE12="","ERROR",IF(AND(OR($S12="ITEM_PRICE_PLUS_DECLARED_DELIVERY",$S12="TOTAL_AMOUNT_INCLUDING_DELIVERY",$S12="ITEM_PRICE_ONLY_DELIVERY_PAID_BY_MERCHANT"),$J12=""),"ERROR",IF(AND(OR($S12="ITEM_PRICE_PLUS_DECLARED_DELIVERY",$S12="DELIVERY_CHARGE_ONLY"),$K12=""),"ERROR",IF(AND(OR($S12="TOTAL_AMOUNT_INCLUDING_DELIVERY",$S12="EXACT_COLLECTION_AMOUNT"),$T12=""),"ERROR",IF(AND($S12="TOTAL_AMOUNT_INCLUDING_DELIVERY",$T12<SUM($J12,$U12)),"ERROR",IF($S12="EXACT_COLLECTION_AMOUNT","REVIEW","OK"))))))))) | AV12: =IF($AU12="","",IF($H12="","Township required",IF($Q12="","Customer tier required",IF($M12="","Weight required",IF($S12="","Amount entry type required",IF(OR($J12<0,$K12<0,$M12<0,$T12<0,$U12<0,$V12<0,$W12<0,$X12<0,$Y12<0),"Negative amounts are not allowed",IF($AE12="","Tariff not found for township and tier",IF(AND(OR($S12="ITEM_PRICE_PLUS_DECLARED_DELIVERY",$S12="TOTAL_AMOUNT_INCLUDING_DELIVERY",$S12="ITEM_PRICE_ONLY_DELIVERY_PAID_BY_MERCHANT"),$J12=""),"Item price required for this amount type",IF(AND(OR($S12="ITEM_PRICE_PLUS_DECLARED_DELIVERY",$S12="DELIVERY_CHARGE_ONLY"),$K12=""),"Declared delivery charge required",IF(AND(OR($S12="TOTAL_AMOUNT_INCLUDING_DELIVERY",$S12="EXACT_COLLECTION_AMOUNT"),$T12=""),"Stated total amount required",IF(AND($S12="TOTAL_AMOUNT_INCLUDING_DELIVERY",$T12<SUM($J12,$U12)),"Stated total is below item price plus additional charge",IF($S12="EXACT_COLLECTION_AMOUNT","Authorized amount breakdown required before settlement","Ready for collection and settlement")))))))))))) | AW12: =IF($AU12="","","PARCEL_FINANCIAL_V2")
L13: =IF($S13="","",IF($S13="ITEM_PRICE_PLUS_DECLARED_DELIVERY",IF(OR($J13="",$K13=""),"",SUM($J13,$K13,$U13)),IF($S13="TOTAL_AMOUNT_INCLUDING_DELIVERY",IF($T13="","",$T13),IF($S13="DELIVERY_CHARGE_ONLY",IF($K13="","",SUM($K13,$U13)),IF($S13="EXACT_COLLECTION_AMOUNT",IF($T13="","",$T13),IF($S13="ITEM_PRICE_ONLY_DELIVERY_PAID_BY_MERCHANT",IF($J13="","",SUM($J13,$U13)),"")))))) | AC13: =IFERROR(VLOOKUP($H13&"|"&$Q13,Tariff_Master!$A$2:$L$169,3,FALSE),"") | AD13: =IFERROR(VLOOKUP($H13&"|"&$Q13,Tariff_Master!$A$2:$L$169,4,FALSE),"") | AE13: =IFERROR(VLOOKUP($H13&"|"&$Q13,Tariff_Master!$A$2:$L$169,6,FALSE),"") | AF13: =IFERROR(VLOOKUP($H13&"|"&$Q13,Tariff_Master!$A$2:$L$169,7,FALSE),"") | AG13: =IFERROR(VLOOKUP($H13&"|"&$Q13,Tariff_Master!$A$2:$L$169,8,FALSE),"") | AH13: =IFERROR(VLOOKUP($H13&"|"&$Q13,Tariff_Master!$A$2:$L$169,9,FALSE),"") | AI13: =IFERROR(VLOOKUP($H13&"|"&$Q13,Tariff_Master!$A$2:$L$169,10,FALSE),"") | AJ13: =IF($M13="","",ROUNDUP(MAX(0,$M13),0)) | AK13: =IF(OR($AJ13="",$AF13=""),"",MAX(0,$AJ13-$AF13)) | AL13: =IF(OR($AK13="",$AG13=""),"",MAX(0,$AK13*$AG13)) | AM13: =IF($AE13="","",MAX(0,SUM($AE13,$AL13,$V13,$W13))) | AN13: =IF($AM13="","",IF(AND($Q13="COMMITMENT",$R13>=$AH13),$AI13,0)) | AO13: =IF($AM13="","",MAX(0,$AM13-$AN13)) | AP13: =IF($S13="","",IF(OR($S13="ITEM_PRICE_PLUS_DECLARED_DELIVERY",$S13="DELIVERY_CHARGE_ONLY"),$K13,IF($S13="TOTAL_AMOUNT_INCLUDING_DELIVERY",IF(OR($T13="",$J13=""),"",MAX(0,$T13-$J13-$U13)),IF($S13="ITEM_PRICE_ONLY_DELIVERY_PAID_BY_MERCHANT",0,"")))) | AQ13: =IF(OR($AP13="",$AO13=""),"",$AP13-$AO13) | AR13: =IF($S13="EXACT_COLLECTION_AMOUNT","BREAKDOWN_REQUIRED",IF($AQ13="","",IF($AQ13>0,"CREDIT_TO_MERCHANT",IF($AQ13<0,"DEDUCT_FROM_MERCHANT","NO_ADJUSTMENT")))) | AS13: =IF(OR($AQ13="",$AR13="BREAKDOWN_REQUIRED"),"",$AQ13) | AT13: =IF(OR($AR13="",$AR13="BREAKDOWN_REQUIRED"),"",SUM($J13,$AQ13,$Y13)-$X13) | AU13: =IF(AND($A13="",$B13="",$F13="",$H13="",$J13="",$K13="",$M13="",$S13=""),"",IF(OR($H13="",$Q13="",$M13="",$S13=""),"ERROR",IF(OR($J13<0,$K13<0,$M13<0,$T13<0,$U13<0,$V13<0,$W13<0,$X13<0,$Y13<0),"ERROR",IF($AE13="","ERROR",IF(AND(OR($S13="ITEM_PRICE_PLUS_DECLARED_DELIVERY",$S13="TOTAL_AMOUNT_INCLUDING_DELIVERY",$S13="ITEM_PRICE_ONLY_DELIVERY_PAID_BY_MERCHANT"),$J13=""),"ERROR",IF(AND(OR($S13="ITEM_PRICE_PLUS_DECLARED_DELIVERY",$S13="DELIVERY_CHARGE_ONLY"),$K13=""),"ERROR",IF(AND(OR($S13="TOTAL_AMOUNT_INCLUDING_DELIVERY",$S13="EXACT_COLLECTION_AMOUNT"),$T13=""),"ERROR",IF(AND($S13="TOTAL_AMOUNT_INCLUDING_DELIVERY",$T13<SUM($J13,$U13)),"ERROR",IF($S13="EXACT_COLLECTION_AMOUNT","REVIEW","OK"))))))))) | AV13: =IF($AU13="","",IF($H13="","Township required",IF($Q13="","Customer tier required",IF($M13="","Weight required",IF($S13="","Amount entry type required",IF(OR($J13<0,$K13<0,$M13<0,$T13<0,$U13<0,$V13<0,$W13<0,$X13<0,$Y13<0),"Negative amounts are not allowed",IF($AE13="","Tariff not found for township and tier",IF(AND(OR($S13="ITEM_PRICE_PLUS_DECLARED_DELIVERY",$S13="TOTAL_AMOUNT_INCLUDING_DELIVERY",$S13="ITEM_PRICE_ONLY_DELIVERY_PAID_BY_MERCHANT"),$J13=""),"Item price required for this amount type",IF(AND(OR($S13="ITEM_PRICE_PLUS_DECLARED_DELIVERY",$S13="DELIVERY_CHARGE_ONLY"),$K13=""),"Declared delivery charge required",IF(AND(OR($S13="TOTAL_AMOUNT_INCLUDING_DELIVERY",$S13="EXACT_COLLECTION_AMOUNT"),$T13=""),"Stated total amount required",IF(AND($S13="TOTAL_AMOUNT_INCLUDING_DELIVERY",$T13<SUM($J13,$U13)),"Stated total is below item price plus additional charge",IF($S13="EXACT_COLLECTION_AMOUNT","Authorized amount breakdown required before settlement","Ready for collection and settlement")))))))))))) | AW13: =IF($AU13="","","PARCEL_FINANCIAL_V2")
... L1001: =IF($S1001="","",IF($S1001="ITEM_PRICE_PLUS_DECLARED_DELIVERY",IF(OR($J1001="",$K1001=""),"",SUM($J1001,$K1001,$U1001)),IF($S1001="TOTAL_AMOUNT_INCLUDING_DELIVERY",IF($T1001="","",$T1001),IF($S1001="DELIVERY_CHARGE_ONLY",IF($K1001="","",SUM($K1001,$U1001)),IF($S1001="EXACT_COLLECTION_AMOUNT",IF($T1001="","",$T1001),IF($S1001="ITEM_PRICE_ONLY_DELIVERY_PAID_BY_MERCHANT",IF($J1001="","",SUM($J1001,$U1001)),"")))))) | AC1001: =IFERROR(VLOOKUP($H1001&"|"&$Q1001,Tariff_Master!$A$2:$L$169,3,FALSE),"") | AD1001: =IFERROR(VLOOKUP($H1001&"|"&$Q1001,Tariff_Master!$A$2:$L$169,4,FALSE),"") | AE1001: =IFERROR(VLOOKUP($H1001&"|"&$Q1001,Tariff_Master!$A$2:$L$169,6,FALSE),"") | AF1001: =IFERROR(VLOOKUP($H1001&"|"&$Q1001,Tariff_Master!$A$2:$L$169,7,FALSE),"") | AG1001: =IFERROR(VLOOKUP($H1001&"|"&$Q1001,Tariff_Master!$A$2:$L$169,8,FALSE),"") | AH1001: =IFERROR(VLOOKUP($H1001&"|"&$Q1001,Tariff_Master!$A$2:$L$169,9,FALSE),"") | AI1001: =IFERROR(VLOOKUP($H1001&"|"&$Q1001,Tariff_Master!$A$2:$L$169,10,FALSE),"") | AJ1001: =IF($M1001="","",ROUNDUP(MAX(0,$M1001),0)) | AK1001: =IF(OR($AJ1001="",$AF1001=""),"",MAX(0,$AJ1001-$AF1001)) | AL1001: =IF(OR($AK1001="",$AG1001=""),"",MAX(0,$AK1001*$AG1001)) | AM1001: =IF($AE1001="","",MAX(0,SUM($AE1001,$AL1001,$V1001,$W1001))) | AN1001: =IF($AM1001="","",IF(AND($Q1001="COMMITMENT",$R1001>=$AH1001),$AI1001,0)) | AO1001: =IF($AM1001="","",MAX(0,$AM1001-$AN1001)) | AP1001: =IF($S1001="","",IF(OR($S1001="ITEM_PRICE_PLUS_DECLARED_DELIVERY",$S1001="DELIVERY_CHARGE_ONLY"),$K1001,IF($S1001="TOTAL_AMOUNT_INCLUDING_DELIVERY",IF(OR($T1001="",$J1001=""),"",MAX(0,$T1001-$J1001-$U1001)),IF($S1001="ITEM_PRICE_ONLY_DELIVERY_PAID_BY_MERCHANT",0,"")))) | AQ1001: =IF(OR($AP1001="",$AO1001=""),"",$AP1001-$AO1001) | AR1001: =IF($S1001="EXACT_COLLECTION_AMOUNT","BREAKDOWN_REQUIRED",IF($AQ1001="","",IF($AQ1001>0,"CREDIT_TO_MERCHANT",IF($AQ1001<0,"DEDUCT_FROM_MERCHANT","NO_ADJUSTMENT")))) | AS1001: =IF(OR($AQ1001="",$AR1001="BREAKDOWN_REQUIRED"),"",$AQ1001) | AT1001: =IF(OR($AR1001="",$AR1001="BREAKDOWN_REQUIRED"),"",SUM($J1001,$AQ1001,$Y1001)-$X1001) | AU1001: =IF(AND($A1001="",$B1001="",$F1001="",$H1001="",$J1001="",$K1001="",$M1001="",$S1001=""),"",IF(OR($H1001="",$Q1001="",$M1001="",$S1001=""),"ERROR",IF(OR($J1001<0,$K1001<0,$M1001<0,$T1001<0,$U1001<0,$V1001<0,$W1001<0,$X1001<0,$Y1001<0),"ERROR",IF($AE1001="","ERROR",IF(AND(OR($S1001="ITEM_PRICE_PLUS_DECLARED_DELIVERY",$S1001="TOTAL_AMOUNT_INCLUDING_DELIVERY",$S1001="ITEM_PRICE_ONLY_DELIVERY_PAID_BY_MERCHANT"),$J1001=""),"ERROR",IF(AND(OR($S1001="ITEM_PRICE_PLUS_DECLARED_DELIVERY",$S1001="DELIVERY_CHARGE_ONLY"),$K1001=""),"ERROR",IF(AND(OR($S1001="TOTAL_AMOUNT_INCLUDING_DELIVERY",$S1001="EXACT_COLLECTION_AMOUNT"),$T1001=""),"ERROR",IF(AND($S1001="TOTAL_AMOUNT_INCLUDING_DELIVERY",$T1001<SUM($J1001,$U1001)),"ERROR",IF($S1001="EXACT_COLLECTION_AMOUNT","REVIEW","OK"))))))))) | AV1001: =IF($AU1001="","",IF($H1001="","Township required",IF($Q1001="","Customer tier required",IF($M1001="","Weight required",IF($S1001="","Amount entry type required",IF(OR($J1001<0,$K1001<0,$M1001<0,$T1001<0,$U1001<0,$V1001<0,$W1001<0,$X1001<0,$Y1001<0),"Negative amounts are not allowed",IF($AE1001="","Tariff not found for township and tier",IF(AND(OR($S1001="ITEM_PRICE_PLUS_DECLARED_DELIVERY",$S1001="TOTAL_AMOUNT_INCLUDING_DELIVERY",$S1001="ITEM_PRICE_ONLY_DELIVERY_PAID_BY_MERCHANT"),$J1001=""),"Item price required for this amount type",IF(AND(OR($S1001="ITEM_PRICE_PLUS_DECLARED_DELIVERY",$S1001="DELIVERY_CHARGE_ONLY"),$K1001=""),"Declared delivery charge required",IF(AND(OR($S1001="TOTAL_AMOUNT_INCLUDING_DELIVERY",$S1001="EXACT_COLLECTION_AMOUNT"),$T1001=""),"Stated total amount required",IF(AND($S1001="TOTAL_AMOUNT_INCLUDING_DELIVERY",$T1001<SUM($J1001,$U1001)),"Stated total is below item price plus additional charge",IF($S1001="EXACT_COLLECTION_AMOUNT","Authorized amount breakdown required before settlement","Ready for collection and settlement")))))))))))) | AW1001: =IF($AU1001="","","PARCEL_FINANCIAL_V2")

Sheet Tariff_Master
A1: tariff_key | B1: township | C1: zone | D1: zone_code | E1: customer_tier | F1: base_fee_mmk | G1: included_kg | H1: extra_per_kg_mmk | I1: commitment_min_ways | J1: commitment_refund_per_way | K1: note | L1: status
A2: ပန်းဘဲတန်း|STANDARD | B2: ပန်းဘဲတန်း | C2: Yangon | D2: YGN | E2: STANDARD | F2: 4000 | G2: 3 | H2: 500 | I2: 0 | J2: 0 | L2: active
A3: ပန်းဘဲတန်း|ROYAL | B3: ပန်းဘဲတန်း | C3: Yangon | D3: YGN | E3: ROYAL | F3: 4000 | G3: 5 | H3: 500 | I3: 0 | J3: 0 | L3: active
A4: ပန်းဘဲတန်း|COMMITMENT | B4: ပန်းဘဲတန်း | C4: Yangon | D4: YGN | E4: COMMITMENT | F4: 4000 | G4: 5 | H4: 500 | I4: 1500 | J4: 500 | L4: active
A5: ကျောက်တံတား|STANDARD | B5: ကျောက်တံတား | C5: Yangon | D5: YGN | E5: STANDARD | F5: 4000 | G5: 3 | H5: 500 | I5: 0 | J5: 0 | L5: active
A6: ကျောက်တံတား|ROYAL | B6: ကျောက်တံတား | C6: Yangon | D6: YGN | E6: ROYAL | F6: 4000 | G6: 5 | H6: 500 | I6: 0 | J6: 0 | L6: active
A7: ကျောက်တံတား|COMMITMENT | B7: ကျောက်တံတား | C7: Yangon | D7: YGN | E7: COMMITMENT | F7: 4000 | G7: 5 | H7: 500 | I7: 1500 | J7: 500 | L7: active
A8: လမ်းမတော်|STANDARD | B8: လမ်းမတော် | C8: Yangon | D8: YGN | E8: STANDARD | F8: 4000 | G8: 3 | H8: 500 | I8: 0 | J8: 0 | L8: active
A9: လမ်းမတော်|ROYAL | B9: လမ်းမတော် | C9: Yangon | D9: YGN | E9: ROYAL | F9: 4000 | G9: 5 | H9: 500 | I9: 0 | J9: 0 | L9: active
A10: လမ်းမတော်|COMMITMENT | B10: လမ်းမတော် | C10: Yangon | D10: YGN | E10: COMMITMENT | F10: 4000 | G10: 5 | H10: 500 | I10: 1500 | J10: 500 | L10: active
A11: လသာ|STANDARD | B11: လသာ | C11: Yangon | D11: YGN | E11: STANDARD | F11: 4000 | G11: 3 | H11: 500 | I11: 0 | J11: 0 | L11: active
A12: လသာ|ROYAL | B12: လသာ | C12: Yangon | D12: YGN | E12: ROYAL | F12: 4000 | G12: 5 | H12: 500 | I12: 0 | J12: 0 | L12: active
A13: လသာ|COMMITMENT | B13: လသာ | C13: Yangon | D13: YGN | E13: COMMITMENT | F13: 4000 | G13: 5 | H13: 500 | I13: 1500 | J13: 500 | L13: active
... A79: အင်းစိန်|COMMITMENT | B79: အင်းစိန် | C79: Yangon | D79: YGN | E79: COMMITMENT | F79: 4000 | G79: 5 | H79: 500 | I79: 1500 | J79: 500 | L79: active
A80: မြောက်ဥက္ကလာပ|STANDARD | B80: မြောက်ဥက္ကလာပ | C80: Yangon | D80: YGN | E80: STANDARD | F80: 4500 | G80: 3 | H80: 500 | I80: 0 | J80: 0 | K80: Extended Yangon | L80: active
A81: မြောက်ဥက္ကလာပ|ROYAL | B81: မြောက်ဥက္ကလာပ | C81: Yangon | D81: YGN | E81: ROYAL | F81: 4500 | G81: 5 | H81: 500 | I81: 0 | J81: 0 | K81: Extended Yangon | L81: active
A82: မြောက်ဥက္ကလာပ|COMMITMENT | B82: မြောက်ဥက္ကလာပ | C82: Yangon | D82: YGN | E82: COMMITMENT | F82: 4500 | G82: 5 | H82: 500 | I82: 1500 | J82: 500 | K82: Extended Yangon | L82: active
A83: မင်္ဂလာဒုံ|STANDARD | B83: မင်္ဂလာဒုံ | C83: Yangon | D83: YGN | E83: STANDARD | F83: 4500 | G83: 3 | H83: 500 | I83: 0 | J83: 0 | K83: Extended Yangon | L83: active
A84: မင်္ဂလာဒုံ|ROYAL | B84: မင်္ဂလာဒုံ | C84: Yangon | D84: YGN | E84: ROYAL | F84: 4500 | G84: 5 | H84: 500 | I84: 0 | J84: 0 | K84: Extended Yangon | L84: active
A85: မင်္ဂလာဒုံ|COMMITMENT | B85: မင်္ဂလာဒုံ | C85: Yangon | D85: YGN | E85: COMMITMENT | F85: 4500 | G85: 5 | H85: 500 | I85: 1500 | J85: 500 | K85: Extended Yangon | L85: active
A86: ရွှေပြည်သာ|STANDARD | B86: ရွှေပြည်သာ | C86: Yangon | D86: YGN | E86: STANDARD | F86: 4500 | G86: 3 | H86: 500 | I86: 0 | J86: 0 | K86: Extended Yangon | L86: active
A87: ရွှေပြည်သာ|ROYAL | B87: ရွှေပြည်သာ | C87: Yangon | D87: YGN | E87: ROYAL | F87: 4500 | G87: 5 | H87: 500 | I87: 0 | J87: 0 | K87: Extended Yangon | L87: active
A88: ရွှေပြည်သာ|COMMITMENT | B88: ရွှေပြည်သာ | C88: Yangon | D88: YGN | E88: COMMITMENT | F88: 4500 | G88: 5 | H88: 500 | I88: 1500 | J88: 500 | K88: Extended Yangon | L88: active
A89: လှိုင်သာယာ|STANDARD | B89: လှိုင်သာယာ | C89: Yangon | D89: YGN | E89: STANDARD | F89: 4500 | G89: 3 | H89: 500 | I89: 0 | J89: 0 | K89: Extended Yangon | L89: active
A90: လှိုင်သာယာ|ROYAL | B90: လှိုင်သာယာ | C90: Yangon | D90: YGN | E90: ROYAL | F90: 4500 | G90: 5 | H90: 500 | I90: 0 | J90: 0 | K90: Extended Yangon | L90: active
A91: လှိုင်သာယာ|COMMITMENT | B91: လှိုင်သာယာ | C91: Yangon | D91: YGN | E91: COMMITMENT | F91: 4500 | G91: 5 | H91: 500 | I91: 1500 | J91: 500 | K91: Extended Yangon | L91: active
... A124: Dagon Thiri Highway Drop Off|COMMITMENT | B124: Dagon Thiri Highway Drop Off | C124: Yangon | D124: YGN | E124: COMMITMENT | F124: 4000 | G124: 5 | H124: 500 | I124: 1500 | J124: 500 | K124: Dagon Thiri highway drop-off | L124: active
A125: အောင်မြေသာစံမြို့နယ်|STANDARD | B125: အောင်မြေသာစံမြို့နယ် | C125: Mandalay | D125: MDY | E125: STANDARD | F125: 6000 | G125: 3 | H125: 500 | I125: 0 | J125: 0 | L125: active
A126: အောင်မြေသာစံမြို့နယ်|ROYAL | B126: အောင်မြေသာစံမြို့နယ် | C126: Mandalay | D126: MDY | E126: ROYAL | F126: 6000 | G126: 5 | H126: 500 | I126: 0 | J126: 0 | L126: active
A127: အောင်မြေသာစံမြို့နယ်|COMMITMENT | B127: အောင်မြေသာစံမြို့နယ် | C127: Mandalay | D127: MDY | E127: COMMITMENT | F127: 6000 | G127: 5 | H127: 500 | I127: 1500 | J127: 500 | L127: active
A128: ချမ်းအေးသာစံမြို့နယ်|STANDARD | B128: ချမ်းအေးသာစံမြို့နယ် | C128: Mandalay | D128: MDY | E128: STANDARD | F128: 6000 | G128: 3 | H128: 500 | I128: 0 | J128: 0 | L128: active
A129: ချမ်းအေးသာစံမြို့နယ်|ROYAL | B129: ချမ်းအေးသာစံမြို့နယ် | C129: Mandalay | D129: MDY | E129: ROYAL | F129: 6000 | G129: 5 | H129: 500 | I129: 0 | J129: 0 | L129: active
A130: ချမ်းအေးသာစံမြို့နယ်|COMMITMENT | B130: ချမ်းအေးသာစံမြို့နယ် | C130: Mandalay | D130: MDY | E130: COMMITMENT | F130: 6000 | G130: 5 | H130: 500 | I130: 1500 | J130: 500 | L130: active
A131: မဟာအောင်မြေမြို့နယ်|STANDARD | B131: မဟာအောင်မြေမြို့နယ် | C131: Mandalay | D131: MDY | E131: STANDARD | F131: 6000 | G131: 3 | H131: 500 | I131: 0 | J131: 0 | L131: active
A132: မဟာအောင်မြေမြို့နယ်|ROYAL | B132: မဟာအောင်မြေမြို့နယ် | C132: Mandalay | D132: MDY | E132: ROYAL | F132: 6000 | G132: 5 | H132: 500 | I132: 0 | J132: 0 | L132: active
A133: မဟာအောင်မြေမြို့နယ်|COMMITMENT | B133: မဟာအောင်မြေမြို့နယ် | C133: Mandalay | D133: MDY | E133: COMMITMENT | F133: 6000 | G133: 5 | H133: 500 | I133: 1500 | J133: 500 | L133: active
A134: ချမ်းမြသာစည်မြို့နယ်|STANDARD | B134: ချမ်းမြသာစည်မြို့နယ် | C134: Mandalay | D134: MDY | E134: STANDARD | F134: 6000 | G134: 3 | H134: 500 | I134: 0 | J134: 0 | L134: active
A135: ချမ်းမြသာစည်မြို့နယ်|ROYAL | B135: ချမ်းမြသာစည်မြို့နယ် | C135: Mandalay | D135: MDY | E135: ROYAL | F135: 6000 | G135: 5 | H135: 500 | I135: 0 | J135: 0 | L135: active
A136: ချမ်းမြသာစည်မြို့နယ်|COMMITMENT | B136: ချမ်းမြသာစည်မြို့နယ် | C136: Mandalay | D136: MDY | E136: COMMITMENT | F136: 6000 | G136: 5 | H136: 500 | I136: 1500 | J136: 500 | L136: active
... A169: Naypyitaw|COMMITMENT | B169: Naypyitaw | C169: Nay Pyi Taw | D169: NPT | E169: COMMITMENT | F169: 6000 | G169: 5 | H169: 500 | I169: 1500 | J169: 500 | L169: active

Sheet Backend_Import_Rules
A1: field | B1: classification | C1: backend behaviour | D1: reason
A2: item_price | B2: RAW INPUT | C2: Accept; validate non-negative. | D2: Merchant product value.
A3: delivery_charges | B3: RAW INPUT | C3: Accept as merchant-declared receiver-facing delivery amount. | D3: Must stay separate from the company tariff.
A4: weight_kg | B4: RAW INPUT | C4: Accept; calculate chargeable weight with CEILING. | D4: Tariff calculation input.
A5: amount_entry_type | B5: RAW INPUT | C5: Accept only the five controlled values. | D5: Determines receiver collection logic.
A6: merchant_stated_total_amount | B6: RAW INPUT | C6: Accept only for relevant amount-entry types. | D6: Merchant-written total or exact collection amount.
A7: additional_customer_charge | B7: RAW INPUT | C7: Accept; default zero. | D7: Added to receiver collection but excluded from current merchant settlement rule.
A8: cbm_surcharge | B8: RAW INPUT | C8: Accept; default zero. | D8: Company tariff component.
A9: other_surcharge | B9: RAW INPUT | C9: Accept; default zero. | D9: Approved company tariff component.
A10: merchant_payable_charges | B10: RAW INPUT | C10: Accept; default zero. | D10: Deducted from merchant settlement.
A11: other_merchant_credits | B11: RAW INPUT | C11: Accept; default zero. | D11: Credited to merchant settlement.
A12: customer_tier | B12: BACKEND RESOLVED | C12: Resolve from merchant profile; compare spreadsheet value only as a warning. | D12: Client tier is not authoritative.
... A19: calculation_version / calculated_at | B19: BACKEND CALCULATED | C19: Ignore import and overwrite. | D19: Provides historical rule traceability.

Sheet Instructions
B2: Parcel Collection and Merchant Settlement — Data Entry Guide
B4: Purpose | C4: Keep the amount written by the merchant separate from the company tariff. The receiver pays the parcel instruction; any difference is settled with the merchant.
B5: delivery_charges | C5: Enter the merchant-declared delivery amount written on the parcel. Example: enter 6,000 even when the company tariff is 4,500.
B6: cod_amount | C6: Do not type over this formula. It is the total amount printed/collected from the receiver based on amount_entry_type.
B7: Merchant charged more | C7: Declared delivery 6,000 − system delivery 4,500 = +1,500. The 1,500 is credited to the merchant at settlement.
B8: Merchant charged less | C8: Declared delivery 3,000 − system delivery 4,500 = −1,500. Collect only 3,000 delivery from the receiver and deduct 1,500 from the merchant settlement.
B9: TOTAL_AMOUNT_INCLUDING_DELIVERY | C9: Enter the one total written on the parcel in merchant_stated_total_amount. The sheet derives the delivery component as total − item price − additional customer charge.
B10: EXACT_COLLECTION_AMOUNT | C10: The receiver total is calculated, but settlement is marked BREAKDOWN_REQUIRED until an authorized item/delivery breakdown is confirmed.
B11: Tariff calculation | C11: Chargeable weight is rounded up to a whole kg. Standard includes 3 kg; Royal and Commitment include 5 kg. Extra weight is 500 MMK/kg.
B12: Commitment rule | C12: A 500 MMK per-way refund applies when the COMMITMENT merchant has at least 1,500 monthly ways.
B13: CBM surcharge | C13: Enter CBM surcharge manually or from a future CBM master. No CBM formula was included in the supplied tariff source.
B14: Final checks | C14: Only finalize rows with validation_status = OK. REVIEW and ERROR rows require correction or authorization.
B16: Color key
B17: Blue cells/text | C17: Data-entry inputs
B18: Green cells/text | C18: Tariff-master lookups
B19: Purple cells | C19: Automatic calculations
B20: Orange cells | C20: Validation and review
B22: Backend authority | C22: Spreadsheet formulas are previews only. The backend must ignore imported calculated fields and recalculate COD, tariff snapshots, differences, settlement, validation, version, and timestamp.
B23: Monthly ways | C23: Do not trust the spreadsheet monthly_ways value. The backend counts qualifying merchant ways from database records.
B24: Customer tier | C24: The merchant profile is authoritative. Spreadsheet tier may be compared only for a mismatch warning.
B25: Settlement gate | C25: Settle only DELIVERED parcels with validation_status=OK and settlement_direction not equal to BREAKDOWN_REQUIRED.
B26: Historical protection | C26: After waybill printing, financial recalculation requires authorization. Delivered or settled parcels use adjustment transactions rather than direct edits.

Sheet Examples
A1: scenario | B1: amount_entry_type | C1: item_price | D1: declared_delivery | E1: stated_total | F1: additional_customer_charge | G1: base_tariff | H1: actual_weight_kg | I1: included_kg | J1: extra_per_kg | K1: cbm_surcharge | L1: other_surcharge | M1: commitment_refund | N1: net_system_delivery | O1: total_collect | P1: delivery_difference | Q1: settlement_direction | R1: merchant_settlement | S1: explanation | T1: validation_status | U1: calculation_version
A2: Merchant charged more | B2: ITEM_PRICE_PLUS_DECLARED_DELIVERY | C2: 25000 | D2: 6000 | F2: 0 | G2: 4500 | H2: 1 | I2: 3 | J2: 500 | K2: 0 | L2: 0 | M2: 0 | N2: 4500 | O2: 31000 | P2: 1500 | Q2: CREDIT_TO_MERCHANT | R2: 26500 | S2: Receiver pays declared 6,000; merchant receives the 1,500 excess. | T2: OK | U2: PARCEL_FINANCIAL_V2
